<?xml version="1.0" ?>
<robot name="rs007l" xmlns:xacro="http://ros.org/wiki/xacro">

  <!-- Body Links -->

  <link name="base_link">
    <visual>
      <geometry>
        <mesh filename="RS007/meshes/RS007L_J0.stl"/>
      </geometry>
    </visual>
    <collision>
      <geometry>
        <mesh filename="RS007/meshes/RS007L_J0.stl"/>
      </geometry>
    </collision>
    <xacro:default_inertial mass="11"/>
  </link>

  <link name="link1">
    <visual>
      <geometry>
        <mesh filename="RS007/meshes/RS007L_J1.stl"/>
      </geometry>
    </visual>
    <collision>
      <geometry>
        <mesh filename="RS007/meshes/RS007L_J1.stl"/>
      </geometry>
    </collision>
    <xacro:default_inertial mass="8.188"/>
  </link>

  <link name="link2">
    <visual>
      <geometry>
        <mesh filename="RS007/meshes/RS007L_J2.stl"/>
      </geometry>
    </visual>
    <collision>
      <geometry>
        <mesh filename="RS007/meshes/RS007L_J2.stl"/>
      </geometry>
    </collision>
    <xacro:default_inertial mass="6.826"/>
  </link>

  <link name="link3">
    <visual>
      <geometry>
        <mesh filename="RS007/meshes/RS007L_J3.stl"/>
      </geometry>
    </visual>
    <collision>
      <geometry>
        <mesh filename="RS007/meshes/RS007L_J3.stl"/>
      </geometry>
    </collision>
    <xacro:default_inertial mass="5.236"/>
  </link>

  <link name="link4">
    <visual>
      <geometry>
        <mesh filename="RS007/meshes/RS007L_J4.stl"/>
      </geometry>
    </visual>
    <collision>
      <geometry>
        <mesh filename="RS007/meshes/RS007L_J4.stl"/>
      </geometry>
    </collision>
    <xacro:default_inertial mass="5.066"/>
  </link>

  <link name="link5">
    <visual>
      <geometry>
        <mesh filename="RS007/meshes/RS007L_J5.stl"/>
      </geometry>
    </visual>
    <collision>
      <geometry>
        <mesh filename="RS007/meshes/RS007L_J5.stl"/>
      </geometry>
    </collision>
    <xacro:default_inertial mass="1.625"/>
  </link>

  <link name="link6">
    <visual>
      <geometry>
        <mesh filename="RS007/meshes/RS007L_J6.stl"/>
      </geometry>
    </visual>
    <collision>
      <geometry>
        <mesh filename="RS007/meshes/RS007L_J6.stl"/>
      </geometry>
    </collision>
    <xacro:default_inertial mass="0.625"/>
  </link>

  <!-- Joints -->

  <joint name="joint1" type="revolute">
    <axis xyz="0 0 -1" rpy="0 0 0" />
    <limit effort="1000.0" lower="-3.1416" upper="3.1416" velocity="6.4577"/>
    <origin xyz="0 0 0.36" rpy="0 0 0" />
    <parent link="base_link"/>
    <child link="link1"/>
    <dynamics damping="0.0" friction="0.0"/>
  </joint>

  <joint name="joint2" type="revolute">
    <axis xyz="0 0 1" rpy="0 0 0" />
    <limit effort="1000.0" lower="-2.3562" upper="2.3562" velocity="5.4105"/>
    <origin xyz="0 0 0" rpy="0 -1.57 0" />
    <parent link="link1"/>
    <child link="link2"/>
    <dynamics damping="0.0" friction="0.0"/>
  </joint>

  <joint name="joint3" type="revolute">
    <axis xyz="0 0 -1" rpy="0 0 0" />
    <limit effort="1000.0" lower="-2.7402" upper="2.7402" velocity="7.1559"/>
    <origin xyz="0.455 0 0" rpy="0 0 0" />
    <parent link="link2"/>
    <child link="link3"/>
    <dynamics damping="0.0" friction="0.0"/>
  </joint>

  <joint name="joint4" type="revolute">
    <axis xyz="0 0 1" rpy="0 0 0" />
    <limit effort="1000.0" lower="-3.49066" upper="3.4907" velocity="9.5993"/>
    <origin xyz="0.0925 0 0" rpy="0 1.57 0" />
    <parent link="link3"/>
    <child link="link4"/>
    <dynamics damping="0.0" friction="0.0"/>
  </joint>

  <joint name="joint5" type="revolute">
    <axis xyz="0 0 -1" rpy="0 0 0" />
    <limit effort="1000.0" lower="-2.1817" upper="2.1817" velocity="9.5993"/>
    <origin xyz="0 0 0.3825" rpy="0 -1.57 0" />
    <parent link="link4"/>
    <child link="link5"/>
    <dynamics damping="0.0" friction="0.0"/>
  </joint>

  <joint name="joint6" type="revolute">
    <axis xyz="0 0 1" rpy="0 0 0" />
    <limit effort="1000.0" lower="-6.2832" upper="6.2832" velocity="17.4533"/>
    <origin xyz="0.078 0 0" rpy="0 1.57 0" />
    <parent link="link5"/>
    <child link="link6"/>
    <dynamics damping="0.0" friction="0.0"/>
  </joint>

  <!-- End-Effector -->

  <link name="panda_hand">
    <visual>
      <geometry>
        <mesh filename="package://franka_description/meshes/visual/hand.dae"/>
      </geometry>
    </visual>
    <collision>
      <geometry>
        <mesh filename="package://franka_description/meshes/collision/hand.obj"/>
      </geometry>
    </collision>
  </link>

  <link name="panda_leftfinger">
    <visual>
      <geometry>
        <mesh filename="package://franka_description/meshes/visual/finger.dae"/>
      </geometry>
    </visual>
    <collision>
      <geometry>
        <mesh filename="package://franka_description/meshes/collision/finger.obj"/>
      </geometry>
    </collision>
  </link>
  <link name="panda_rightfinger">
    <visual>
      <origin rpy="0 0 3.14159265359" xyz="0 0 0"/>
      <geometry>
        <mesh filename="package://franka_description/meshes/visual/finger.dae"/>
      </geometry>
    </visual>
    <collision>
      <origin rpy="0 0 3.14159265359" xyz="0 0 0"/>
      <geometry>
        <mesh filename="package://franka_description/meshes/collision/finger.obj"/>
      </geometry>
    </collision>
  </link>

  <joint name="panda_hand_joint" type="fixed">
    <parent link="link6"/>
    <child link="panda_hand"/>
    <origin rpy="0 0 0" xyz="0 0 0"/>
  </joint>

  <joint name="panda_finger_joint1" type="prismatic">
    <parent link="panda_hand"/>
    <child link="panda_leftfinger"/>
    <origin rpy="0 0 0" xyz="0 0 0.0584"/>
    <axis xyz="0 1 0"/>
    <dynamics damping="10.0"/>
    <limit effort="20" lower="0.0" upper="0.04" velocity="0.2"/>
  </joint>
  
  <joint name="panda_finger_joint2" type="prismatic">
    <parent link="panda_hand"/>
    <child link="panda_rightfinger"/>
    <origin rpy="0 0 0" xyz="0 0 0.0584"/>
    <axis xyz="0 -1 0"/>
    <dynamics damping="10.0"/>
    <limit effort="20" lower="0.0" upper="0.04" velocity="0.2"/>
    <mimic joint="panda_finger_joint1"/>
  </joint>

</robot>

